Workbook

Sheet Dashboard
B1: ApexPlanet Sales Performance – Key Metrics Dashboard (Static Mock-up)
B3: ="Data period: "&TEXT(MIN(Data!$B$2:$B$1001),"dd mmm yyyy")&" to "&TEXT(MAX(Data!$B$2:$B$1001),"dd mmm yyyy")&" | "&TEXT(Calc!$B$8,"#,##0")&" orders | Currency assumed INR | Source: Sales_Dataset" -> Data period: 01 Jan 2025 to 01 Jan 2026 | 1,000 orders | Currency assumed INR | Source: Sales_Dataset
B4: HEADLINE KPIs (Tier 1)
B5: TOTAL REVENUE | E5: TOTAL ORDERS | H5: AVG ORDER VALUE (AOV) | K5: UNITS SOLD
B6: =Calc!$B$7/Calc!$B$4 -> 13.939944 | E6: =Calc!$B$8 -> 1000 | H6: =Calc!$B$9 -> 139399.44 | K6: =Calc!$B$10 -> 5435
B7: ="Sum of Total_Sales" -> Sum of Total_Sales | E7: ="Avg "&TEXT(Calc!$B$11,"0.0")&" units per order" -> Avg 5.4 units per order | H7: ="Revenue ÷ orders" -> Revenue ÷ orders | K7: ="Across "&TEXT(COUNTA(Data!$H$2:$H$1001)-COUNTBLANK(Data!$H$2:$H$1001),"#,##0")&" order lines" -> Across 1,000 order lines
B9: UNIQUE CUSTOMERS | E9: REPEAT CUSTOMER RATE | H9: MoM REVENUE GROWTH | K9: TOP CATEGORY SHARE
B10: =Calc!$B$12 -> 947 | E10: =Calc!$B$14 -> 0.054910243 | H10: =Calc!$B$18 -> -0.025952299 | K10: =Calc!$B$21 -> 0.36426676
B11: ="Avg ₹"&TEXT(Calc!$B$15/100000,"0.00")&" lakh revenue per customer" -> Avg ₹1.47 lakh revenue per customer | E11: =TEXT(Calc!$B$13,"0")&" of "&TEXT(Calc!$B$12,"0")&" customers ordered 2+ times" -> 52 of 947 customers ordered 2+ times | H11: =TEXT(Calc!A49,"mmm-yy")&" vs "&TEXT(Calc!A48,"mmm-yy")&" (last full month)" -> Dec-25 vs Nov-25 (last full month) | K11: =Calc!$B$22&" share of total revenue" -> Electronics share of total revenue
B13: TRENDS & BREAKDOWNS (Tier 2)
B62: KEY TAKEAWAYS FROM EDA
B63: • Revenue is concentrated in Electronics: 36.4% of revenue (Laptop + Mobile) while the other four categories hold 14–18% each.
B64: • Retention is the biggest gap: only 52 of 947 customers (5.5%) ordered more than once, and none more than 3 times.
B65: • Revenue peaked in Mar-25 (₹131 Lakh) and bottomed in Sep-25 (₹92 Lakh); Dec-25 closed -2.6% vs Nov-25.
B66: • Patna leads on revenue (₹193 Lakh) but Bengaluru has the highest AOV (₹1.54 Lakh); Gaya is lowest on revenue (₹144 Lakh).
B68: DATA-QUALITY WATCH (Tier 3)
B69: Missing City | E69: Missing Age | H69: Reused Order_IDs | K69: Jan-26 partial month
B70: =TEXT(Calc!$B$27,"0")&" rows ("&TEXT(Calc!$B$28,"0.0%")&")" -> 13 rows (1.3%) | E70: =TEXT(Calc!$B$25,"0")&" rows ("&TEXT(Calc!$B$26,"0.0%")&")" -> 20 rows (2.0%) | H70: =TEXT(Calc!$B$24,"0")&" duplicate-ID rows" -> 8 duplicate-ID rows | K70: =TEXT(Calc!$B$30,"0")&" orders (excluded from trend)" -> 5 orders (excluded from trend)
B72: Static mock-up: layout and KPI selection are the deliverable. Figures are formula-driven from the Data/Calc sheets and reflect the dataset at build time; no slicers or interactivity. ₹ Cr = 10,000,000; ₹ Lakh = 100,000.

Sheet KPI_Framework
A1: Proposed KPI Framework – what to track and why
A2: Prioritised from the EDA. Current values are live links to the Calc sheet. Targets are intentionally left for business stakeholders – none are invented here.
A4: # | B4: Tier | C4: KPI | D4: Definition / formula | E4: Current value | F4: Why it matters (EDA evidence) | G4: Suggested visual | H4: Cadence | I4: Proposed alert rule (to validate)
A5: 1 | B5: Tier 1 – Headline | C5: Total Revenue | D5: SUM(Total_Sales) | E5: =Calc!$B$7 -> 1.3939944e+08 | F5: Core scale metric. Total_Sales reconciles exactly to Quantity × Unit_Price on every row, so it is a reliable revenue measure. | G5: KPI card + monthly line | H5: Daily / monthly | I5: Month < 90% of trailing-3-month average
A6: 2 | B6: Tier 1 – Headline | C6: Total Orders | D6: COUNT(order rows) | E6: =Calc!$B$8 -> 1000 | F6: Volume driver. Order_ID is not unique (reused IDs), so count rows, not distinct IDs, until the source is fixed. | G6: KPI card | H6: Daily / monthly | I6: Orders fall while AOV is flat
A7: 3 | B7: Tier 1 – Headline | C7: Average Order Value (AOV) | D7: Total Revenue ÷ Total Orders | E7: =Calc!$B$9 -> 139399.44 | F7: Separates growth from volume vs. basket size. AOV varies by city (Bengaluru highest, Gaya lowest) and by category. | G7: KPI card + AOV by city | H7: Monthly | I7: AOV drops > 5% MoM
A8: 4 | B8: Tier 1 – Headline | C8: Unique Customers | D8: DISTINCT(Customer_ID) | E8: =Calc!$B$12 -> 947 | F8: 947 distinct IDs for 1,000 orders. Customer_ID (not Customer_Name, which repeats across IDs) must be the key. | G8: KPI card | H8: Monthly | I8: New-customer count falls 2 months in a row
A9: 5 | B9: Tier 1 – Headline | C9: Repeat Customer Rate | D9: Customers with 2+ orders ÷ Unique Customers | E9: =Calc!$B$14 -> 0.054910243 | F9: Very low baseline: retention is the largest improvement opportunity visible in the data. | G9: KPI card + trend | H9: Monthly / quarterly | I9: Any decline vs. prior quarter
A10: 6 | B10: Tier 1 – Headline | C10: MoM Revenue Growth | D10: Latest full month ÷ prior month − 1 | E10: =Calc!$B$18 -> -0.025952299 | F10: Revenue is seasonal: peak in Mar-25, trough in Aug–Sep-25, recovery in Oct-25. Growth rate flags turns early. | G10: KPI card + monthly line | H10: Monthly | I10: Two consecutive negative months
A11: 7 | B11: Tier 2 – Diagnostic | C11: Category revenue share | D11: Category revenue ÷ Total Revenue | E11: =Calc!$B$21 -> 0.36426676 | F11: Electronics holds ~36% of revenue; a dip in one category moves the whole business. | G11: Horizontal bar | H11: Monthly | I11: Any category share moves > 3 pts MoM
A12: 8 | B12: Tier 2 – Diagnostic | C12: Product revenue & units | D12: SUM(Total_Sales), SUM(Quantity) by Product | E12: =Calc!$B$68 -> 254.43009 | F12: Six products contribute 14–18% each, so no single hero SKU. Shoes is lowest on revenue and AOV. (Value shown: top product, ₹ Lakh.) | G12: Column chart | H12: Monthly | I12: Product share < 12%
A13: 9 | B13: Tier 2 – Diagnostic | C13: City revenue & AOV | D13: SUM(Total_Sales) and AOV by City | E13: =Calc!$B$23 -> Patna | F13: Patna, Kolkata, Bengaluru, Mumbai lead; Pune and Gaya trail. Bengaluru wins on basket size, Patna on order count. (Value shown: top city.) | G13: Horizontal bar + AOV | H13: Monthly | I13: City revenue −10% vs. 3-month avg
A14: 10 | B14: Tier 2 – Diagnostic | C14: Revenue by age group | D14: SUM(Total_Sales) by Age band | E14: =Calc!$B$94 -> 296.32337 | F14: 26–35 is the biggest segment; 18–25 the smallest. Differences are modest. (Value shown: 26–35 revenue, ₹ Lakh.) | G14: Column chart | H14: Quarterly | I14: Segment share shifts > 3 pts
A15: 11 | B15: Tier 2 – Diagnostic | C15: Gender revenue split | D15: SUM(Total_Sales) by Gender | E15: =Calc!$F$104 -> 0.5198267 | F15: Near 52/48 split with a small AOV gap; low priority, kept as context. (Value shown: male share.) | G15: Doughnut | H15: Quarterly | I15: Not alert-worthy
A16: 12 | B16: Tier 3 – Data health | C16: Missing City / Age % | D16: Blank City ÷ rows; Blank Age ÷ rows | E16: =Calc!$B$28 -> 0.013 | F16: 13 rows lack City (~₹15 Lakh revenue unattributable); 20 rows lack Age. (Value shown: missing-City %.) | G16: Warning strip | H16: Each load | I16: > 2% on either field
A17: 13 | B17: Tier 3 – Data health | C17: Duplicate Order_ID rows | D17: Rows − distinct Order_IDs | E17: =Calc!$B$24 -> 8 | F17: ORD100050 appears 9 times with different customers and dates – an ID-generation issue to raise with the data owner. | G17: Warning strip | H17: Each load | I17: > 0
A18: 14 | B18: Tier 3 – Data health | C18: Line-total mismatches | D18: Rows where Qty × Price ≠ Total_Sales | E18: =Calc!$B$29 -> 0 | F18: Currently zero – keep monitoring so the revenue KPI stays trustworthy. | G18: Warning strip | H18: Each load | I18: > 0
A20: Alert rules are proposals for discussion, not agreed thresholds. Currency assumed INR.

Sheet EDA_Insights
A1: EDA Insights that shaped the KPI selection
A2: Findings are a snapshot from exploratory analysis of Sales_Dataset (computed at build time).
A4: # | B4: Theme | C4: Finding | D4: Implication for the dashboard
A5: 1 | B5: Data profile | C5: 1,000 transaction rows, 12 columns, 01 Jan 2025 to 01 Jan 2026; 6 products in 5 categories sold across 8 cities. Total revenue ₹13.94 Cr. | D5: Small, clean-enough dataset; a single-page dashboard is the right size.
A6: 2 | B6: Revenue integrity | C6: Quantity × Unit_Price equals Total_Sales on all 1,000 rows (0 mismatches). | D6: Total_Sales can be used directly as the revenue measure.
A7: 3 | B7: Category mix | C7: Electronics = 36.4% of revenue and 35.4% of orders. Education 18.0%, Grocery 15.9%, Furniture 15.4%, Fashion 14.2%. | D7: Track category share and top-category share as a concentration KPI.
A8: 4 | B8: Product mix | C8: Laptop 18.3%, Mobile 18.2%, Book 18.0%, Rice 15.9%, Chair 15.4%, Shoes 14.2%. Shoes has the lowest AOV (₹1.27 Lakh). | D8: No single hero product; show product revenue as a simple column chart.
A9: 5 | B9: Geography | C9: Patna is the top city (₹193 Lakh, 13.8%), Gaya the lowest (₹144 Lakh). AOV ranges from ₹1.23 Lakh (Gaya) to ₹1.54 Lakh (Bengaluru). | D9: Show city revenue plus AOV: volume and basket size tell different stories.
A10: 6 | B10: Seasonality | C10: Monthly revenue ranges from ₹92 Lakh (Sep-25) to ₹131 Lakh (Mar-25); Aug–Sep dip, then Oct recovery (₹125 Lakh). Dec-25 is -2.6% vs Nov-25. | D10: A monthly trend line and MoM growth are essential; consider YoY once a second year exists.
A11: 7 | B11: Customers | C11: 947 distinct Customer_IDs across 1,000 orders; only 52 repeat customers (5.5%), max 3 orders. 425 customer names map to 947 IDs, so names are not unique. | D11: Repeat Customer Rate is a priority KPI; always key on Customer_ID.
A12: 8 | B12: Demographics | C12: Age 18–65 (mean 41); 26–35 is the biggest revenue band (₹296 Lakh), 18–25 the smallest (₹223 Lakh). Male 52% / Female 48% of revenue; AOV ₹1.42 vs ₹1.37 Lakh. | D12: Differences are small; keep as contextual Tier 2 visuals, not headline KPIs.
A13: 9 | B13: Pricing realism | C13: Quantity is spread evenly from 1 to 10 and average unit price is similar for every product (₹24,728–₹26,360); Rice is priced like a Laptop. | D13: The data looks synthetic. Treat product-price KPIs with caution; focus on revenue, orders and customers.
A14: 10 | B14: Data quality | C14: 13 rows missing City (₹15.4 Lakh), 20 missing Age, 8 duplicate Order_ID rows (ORD100050 appears 9 times), 5 orders on 01 Jan 2026 only. | D14: Add a data-quality strip; show missing City as “Unknown”; exclude the partial month from the trend.

Sheet Calc
A1: Calculation layer – every dashboard number is computed here from the Data sheet
A2: Assumptions
A3: ₹ Lakh divisor | B3: 100000 | C3: Assumption: 1 Lakh = 100,000. Currency assumed INR (dataset has no currency field; cities are Indian).
A4: Crore divisor | B4: 10000000 | C4: Assumption: 1 Crore = 10,000,000.
A6: Headline KPI | B6: Value | C6: Definition
A7: Total Revenue (₹) | B7: =SUM(Data!$L$2:$L$1001) -> 1.3939944e+08 | C7: Sum of Total_Sales
A8: Total Orders | B8: =COUNTA(Data!$A$2:$A$1001) -> 1000 | C8: Count of transaction rows (Order_ID is not unique – see data-quality block)
A9: Average Order Value (₹) | B9: =B7/B8 -> 139399.44 | C9: Total Revenue ÷ Total Orders
A10: Units Sold | B10: =SUM(Data!$J$2:$J$1001) -> 5435 | C10: Sum of Quantity
A11: Units per Order | B11: =B10/B8 -> 5.435 | C11: Units Sold ÷ Total Orders
A12: Unique Customers | B12: =SUM(Data!$Q$2:$Q$1001) -> 947 | C12: Distinct Customer_ID
A13: Repeat Customers | B13: =SUMPRODUCT(Data!$Q$2:$Q$1001*(Data!$P$2:$P$1001>1)) -> 52 | C13: Customers with 2+ orders
A14: Repeat Customer Rate | B14: =B13/B12 -> 0.054910243 | C14: Repeat Customers ÷ Unique Customers
A15: Revenue per Customer (₹) | B15: =B7/B12 -> 147201.1 | C15: Total Revenue ÷ Unique Customers
A16: Latest full month revenue (₹ Lakh) | B16: =C49 -> 122.99904 | C16: Dec-25 – last complete month in the data
A17: Prior month revenue (₹ Lakh) | B17: =C48 -> 126.2762
A18: MoM Revenue Growth | B18: =IF(B17=0,0,B16/B17-1) -> -0.025952299 | C18: Latest full month ÷ prior month − 1
A20: Concentration & data-quality metrics | B20: Value | C20: Definition
A21: Top category revenue share | B21: =MAX(F58:F62) -> 0.36426676 | C21: Largest category share of total revenue
A22: Top category | B22: =INDEX(A58:A62,MATCH(MAX(F58:F62),F58:F62,0)) -> Electronics | C22: Category with the highest revenue
A23: Top city | B23: =INDEX(A79:A86,MATCH(MAX(B79:B86),B79:B86,0)) -> Patna | C23: City with the highest revenue (excl. Unknown)
A24: Order_IDs reused (duplicate rows) | B24: =B8-SUMPRODUCT(1/COUNTIF(Data!$A$2:$A$1001,Data!$A$2:$A$1001)) -> 8 | C24: Rows − distinct Order_IDs
A25: Missing Age (rows) | B25: =COUNTBLANK(Data!$E$2:$E$1001) -> 20 | C25: Blank Age
A26: Missing Age % | B26: =B25/B8 -> 0.02
A27: Missing City (rows) | B27: =COUNTBLANK(Data!$G$2:$G$1001) -> 13 | C27: Blank City
A28: Missing City % | B28: =B27/B8 -> 0.013
A29: Line-total mismatches | B29: =SUMPRODUCT(--(ABS(Data!$J$2:$J$1001*Data!$K$2:$K$1001-Data!$L$2:$L$1001)>0.05)) -> 0 | C29: Rows where Quantity × Unit_Price ≠ Total_Sales (tolerance ₹0.05)
A30: Orders dated Jan-26 (partial month) | B30: =D51 -> 5 | C30: Excluded from monthly trend; included in headline totals
A31: Revenue with missing City (₹ Lakh) | B31: =B87 -> 15.406175 | C31: Revenue that cannot be attributed to a city
A36: Monthly Revenue Trend (calendar 2025)
A37: Month | B37: Label | C37: Revenue (₹ Lakh) | D37: Orders | E37: AOV (₹) | F37: MoM Growth
A38: 45658 | B38: =TEXT(A38,"mmm-yy") -> Jan-25 | C38: =SUMIFS(Data!$L$2:$L$1001,Data!$M$2:$M$1001,$A38)/$B$3 -> 100.96191 | D38: =COUNTIFS(Data!$M$2:$M$1001,$A38) -> 76 | E38: =IF(D38=0,0,C38*$B$3/D38) -> 132844.61
A39: 45689 | B39: =TEXT(A39,"mmm-yy") -> Feb-25 | C39: =SUMIFS(Data!$L$2:$L$1001,Data!$M$2:$M$1001,$A39)/$B$3 -> 115.11181 | D39: =COUNTIFS(Data!$M$2:$M$1001,$A39) -> 86 | E39: =IF(D39=0,0,C39*$B$3/D39) -> 133850.95 | F39: =IF(C38=0,0,C39/C38-1) -> 0.14015095
A40: 45717 | B40: =TEXT(A40,"mmm-yy") -> Mar-25 | C40: =SUMIFS(Data!$L$2:$L$1001,Data!$M$2:$M$1001,$A40)/$B$3 -> 130.599 | D40: =COUNTIFS(Data!$M$2:$M$1001,$A40) -> 89 | E40: =IF(D40=0,0,C40*$B$3/D40) -> 146740.45 | F40: =IF(C39=0,0,C40/C39-1) -> 0.13454036
A41: 45748 | B41: =TEXT(A41,"mmm-yy") -> Apr-25 | C41: =SUMIFS(Data!$L$2:$L$1001,Data!$M$2:$M$1001,$A41)/$B$3 -> 122.227 | D41: =COUNTIFS(Data!$M$2:$M$1001,$A41) -> 80 | E41: =IF(D41=0,0,C41*$B$3/D41) -> 152783.75 | F41: =IF(C40=0,0,C41/C40-1) -> -0.064104608
A42: 45778 | B42: =TEXT(A42,"mmm-yy") -> May-25 | C42: =SUMIFS(Data!$L$2:$L$1001,Data!$M$2:$M$1001,$A42)/$B$3 -> 109.84689 | D42: =COUNTIFS(Data!$M$2:$M$1001,$A42) -> 85 | E42: =IF(D42=0,0,C42*$B$3/D42) -> 129231.64 | F42: =IF(C41=0,0,C42/C41-1) -> -0.10128784
A43: 45809 | B43: =TEXT(A43,"mmm-yy") -> Jun-25 | C43: =SUMIFS(Data!$L$2:$L$1001,Data!$M$2:$M$1001,$A43)/$B$3 -> 129.12333 | D43: =COUNTIFS(Data!$M$2:$M$1001,$A43) -> 83 | E43: =IF(D43=0,0,C43*$B$3/D43) -> 155570.27 | F43: =IF(C42=0,0,C43/C42-1) -> 0.17548456
A44: 45839 | B44: =TEXT(A44,"mmm-yy") -> Jul-25 | C44: =SUMIFS(Data!$L$2:$L$1001,Data!$M$2:$M$1001,$A44)/$B$3 -> 117.46227 | D44: =COUNTIFS(Data!$M$2:$M$1001,$A44) -> 83 | E44: =IF(D44=0,0,C44*$B$3/D44) -> 141520.8 | F44: =IF(C43=0,0,C44/C43-1) -> -0.090309464
A45: 45870 | B45: =TEXT(A45,"mmm-yy") -> Aug-25 | C45: =SUMIFS(Data!$L$2:$L$1001,Data!$M$2:$M$1001,$A45)/$B$3 -> 94.484712 | D45: =COUNTIFS(Data!$M$2:$M$1001,$A45) -> 75 | E45: =IF(D45=0,0,C45*$B$3/D45) -> 125979.62 | F45: =IF(C44=0,0,C45/C44-1) -> -0.19561648
A46: 45901 | B46: =TEXT(A46,"mmm-yy") -> Sep-25 | C46: =SUMIFS(Data!$L$2:$L$1001,Data!$M$2:$M$1001,$A46)/$B$3 -> 91.798963 | D46: =COUNTIFS(Data!$M$2:$M$1001,$A46) -> 79 | E46: =IF(D46=0,0,C46*$B$3/D46) -> 116201.22 | F46: =IF(C45=0,0,C46/C45-1) -> -0.028425226
...

Sheet Data
A1: Order_ID | B1: Order_Date | C1: Customer_ID | D1: Customer_Name | E1: Age | F1: Gender | G1: City | H1: Product | I1: Category | J1: Quantity | K1: Unit_Price | L1: Total_Sales | M1: Order_Month | N1: City_Clean | O1: Age_Group | P1: Cust_Order_Count | Q1: Cust_First_Flag
A2: ORD100002 | B2: 45713 | C2: CUST5529 | D2: Customer_227 | E2: 30 | F2: Female | G2: Bengaluru | H2: Rice | I2: Grocery | J2: 7 | K2: 2829.77 | L2: 19808.39 | M2: =DATE(YEAR(B2),MONTH(B2),1) -> 45689 | N2: =IF(G2="","Unknown",G2) -> Bengaluru | O2: =IF(E2="","Unknown",IF(E2<=25,"18-25",IF(E2<=35,"26-35",IF(E2<=45,"36-45",IF(E2<=55,"46-55","56-65"))))) -> 26-35 | P2: =COUNTIF($C$2:$C$1001,C2) -> 1 | Q2: =IF(COUNTIF($C$2:C2,C2)=1,1,0) -> 1
A3: ORD100003 | B3: 45944 | C3: CUST3127 | D3: Customer_182 | E3: 63 | F3: Male | G3: Bengaluru | H3: Book | I3: Education | J3: 5 | K3: 27906.16 | L3: 139530.8 | M3: =DATE(YEAR(B3),MONTH(B3),1) -> 45931 | N3: =IF(G3="","Unknown",G3) -> Bengaluru | O3: =IF(E3="","Unknown",IF(E3<=25,"18-25",IF(E3<=35,"26-35",IF(E3<=45,"36-45",IF(E3<=55,"46-55","56-65"))))) -> 56-65 | P3: =COUNTIF($C$2:$C$1001,C3) -> 1 | Q3: =IF(COUNTIF($C$2:C3,C3)=1,1,0) -> 1
A4: ORD100004 | B4: 45790 | C4: CUST8887 | D4: Customer_487 | E4: 62 | F4: Female | G4: Bengaluru | H4: Book | I4: Education | J4: 8 | K4: 37491.06 | L4: 299928.48 | M4: =DATE(YEAR(B4),MONTH(B4),1) -> 45778 | N4: =IF(G4="","Unknown",G4) -> Bengaluru | O4: =IF(E4="","Unknown",IF(E4<=25,"18-25",IF(E4<=35,"26-35",IF(E4<=45,"36-45",IF(E4<=55,"46-55","56-65"))))) -> 56-65 | P4: =COUNTIF($C$2:$C$1001,C4) -> 1 | Q4: =IF(COUNTIF($C$2:C4,C4)=1,1,0) -> 1
A5: ORD100005 | B5: 45993 | C5: CUST2515 | D5: Customer_470 | E5: 65 | F5: Female | G5: Kolkata | H5: Mobile | I5: Electronics | J5: 9 | K5: 28541.36 | L5: 256872.24 | M5: =DATE(YEAR(B5),MONTH(B5),1) -> 45992 | N5: =IF(G5="","Unknown",G5) -> Kolkata | O5: =IF(E5="","Unknown",IF(E5<=25,"18-25",IF(E5<=35,"26-35",IF(E5<=45,"36-45",IF(E5<=55,"46-55","56-65"))))) -> 56-65 | P5: =COUNTIF($C$2:$C$1001,C5) -> 3 | Q5: =IF(COUNTIF($C$2:C5,C5)=1,1,0) -> 1
A6: ORD100006 | B6: 45981 | C6: CUST4796 | D6: Customer_380 | E6: 44 | F6: Male | G6: Bengaluru | H6: Rice | I6: Grocery | J6: 10 | K6: 14036.59 | L6: 140365.9 | M6: =DATE(YEAR(B6),MONTH(B6),1) -> 45962 | N6: =IF(G6="","Unknown",G6) -> Bengaluru | O6: =IF(E6="","Unknown",IF(E6<=25,"18-25",IF(E6<=35,"26-35",IF(E6<=45,"36-45",IF(E6<=55,"46-55","56-65"))))) -> 36-45 | P6: =COUNTIF($C$2:$C$1001,C6) -> 1 | Q6: =IF(COUNTIF($C$2:C6,C6)=1,1,0) -> 1
A7: ORD100007 | B7: 46022 | C7: CUST3952 | D7: Customer_71 | E7: 40 | F7: Female | G7: Hyderabad | H7: Laptop | I7: Electronics | J7: 9 | K7: 35947.47 | L7: 323527.23 | M7: =DATE(YEAR(B7),MONTH(B7),1) -> 45992 | N7: =IF(G7="","Unknown",G7) -> Hyderabad | O7: =IF(E7="","Unknown",IF(E7<=25,"18-25",IF(E7<=35,"26-35",IF(E7<=45,"36-45",IF(E7<=55,"46-55","56-65"))))) -> 36-45 | P7: =COUNTIF($C$2:$C$1001,C7) -> 1 | Q7: =IF(COUNTIF($C$2:C7,C7)=1,1,0) -> 1
A8: ORD100008 | B8: 45944 | C8: CUST1758 | D8: Customer_335 | E8: 61 | F8: Male | G8: Patna | H8: Mobile | I8: Electronics | J8: 6 | K8: 49997.53 | L8: 299985.18 | M8: =DATE(YEAR(B8),MONTH(B8),1) -> 45931 | N8: =IF(G8="","Unknown",G8) -> Patna | O8: =IF(E8="","Unknown",IF(E8<=25,"18-25",IF(E8<=35,"26-35",IF(E8<=45,"36-45",IF(E8<=55,"46-55","56-65"))))) -> 56-65 | P8: =COUNTIF($C$2:$C$1001,C8) -> 1 | Q8: =IF(COUNTIF($C$2:C8,C8)=1,1,0) -> 1
A9: ORD100009 | B9: 45996 | C9: CUST9622 | D9: Customer_224 | E9: 35 | F9: Male | G9: Kolkata | H9: Laptop | I9: Electronics | J9: 3 | K9: 9488.83 | L9: 28466.49 | M9: =DATE(YEAR(B9),MONTH(B9),1) -> 45992 | N9: =IF(G9="","Unknown",G9) -> Kolkata | O9: =IF(E9="","Unknown",IF(E9<=25,"18-25",IF(E9<=35,"26-35",IF(E9<=45,"36-45",IF(E9<=55,"46-55","56-65"))))) -> 26-35 | P9: =COUNTIF($C$2:$C$1001,C9) -> 1 | Q9: =IF(COUNTIF($C$2:C9,C9)=1,1,0) -> 1
A10: ORD100010 | B10: 45982 | C10: CUST9770 | D10: Customer_494 | E10: 41 | F10: Female | G10: Mumbai | H10: Book | I10: Education | J10: 6 | K10: 19488.23 | L10: 116929.38 | M10: =DATE(YEAR(B10),MONTH(B10),1) -> 45962 | N10: =IF(G10="","Unknown",G10) -> Mumbai | O10: =IF(E10="","Unknown",IF(E10<=25,"18-25",IF(E10<=35,"26-35",IF(E10<=45,"36-45",IF(E10<=55,"46-55","56-65"))))) -> 36-45 | P10: =COUNTIF($C$2:$C$1001,C10) -> 1 | Q10: =IF(COUNTIF($C$2:C10,C10)=1,1,0) -> 1
A11: ORD100011 | B11: 45763 | C11: CUST1312 | D11: Customer_40 | E11: 30 | F11: Male | G11: Kolkata | H11: Mobile | I11: Electronics | J11: 8 | K11: 18024.34 | L11: 144194.72 | M11: =DATE(YEAR(B11),MONTH(B11),1) -> 45748 | N11: =IF(G11="","Unknown",G11) -> Kolkata | O11: =IF(E11="","Unknown",IF(E11<=25,"18-25",IF(E11<=35,"26-35",IF(E11<=45,"36-45",IF(E11<=55,"46-55","56-65"))))) -> 26-35 | P11: =COUNTIF($C$2:$C$1001,C11) -> 1 | Q11: =IF(COUNTIF($C$2:C11,C11)=1,1,0) -> 1
A12: ORD100012 | B12: 45782 | C12: CUST9642 | D12: Customer_162 | E12: 51 | F12: Male | G12: Delhi | H12: Shoes | I12: Fashion | J12: 3 | K12: 14151.42 | L12: 42454.26 | M12: =DATE(YEAR(B12),MONTH(B12),1) -> 45778 | N12: =IF(G12="","Unknown",G12) -> Delhi | O12: =IF(E12="","Unknown",IF(E12<=25,"18-25",IF(E12<=35,"26-35",IF(E12<=45,"36-45",IF(E12<=55,"46-55","56-65"))))) -> 46-55 | P12: =COUNTIF($C$2:$C$1001,C12) -> 1 | Q12: =IF(COUNTIF($C$2:C12,C12)=1,1,0) -> 1
A13: ORD100013 | B13: 45779 | C13: CUST3228 | D13: Customer_209 | E13: 55 | F13: Female | G13: Patna | H13: Chair | I13: Furniture | J13: 6 | K13: 47175.43 | L13: 283052.58 | M13: =DATE(YEAR(B13),MONTH(B13),1) -> 45778 | N13: =IF(G13="","Unknown",G13) -> Patna | O13: =IF(E13="","Unknown",IF(E13<=25,"18-25",IF(E13<=35,"26-35",IF(E13<=45,"36-45",IF(E13<=55,"46-55","56-65"))))) -> 46-55 | P13: =COUNTIF($C$2:$C$1001,C13) -> 1 | Q13: =IF(COUNTIF($C$2:C13,C13)=1,1,0) -> 1
... A49: ORD100049 | B49: 45955 | C49: CUST2705 | D49: Customer_117 | E49: 55 | F49: Male | G49: Kolkata | H49: Mobile | I49: Electronics | J49: 5 | K49: 24854.05 | L49: 124270.25 | M49: =DATE(YEAR(B49),MONTH(B49),1) -> 45931 | N49: =IF(G49="","Unknown",G49) -> Kolkata | O49: =IF(E49="","Unknown",IF(E49<=25,"18-25",IF(E49<=35,"26-35",IF(E49<=45,"36-45",IF(E49<=55,"46-55","56-65"))))) -> 46-55 | P49: =COUNTIF($C$2:$C$1001,C49) -> 1 | Q49: =IF(COUNTIF($C$2:C49,C49)=1,1,0) -> 1
A50: ORD100050 | B50: 45933 | C50: CUST5523 | D50: Customer_432 | F50: Male | G50: Pune | H50: Chair | I50: Furniture | J50: 9 | K50: 30834.87 | L50: 277513.83 | M50: =DATE(YEAR(B50),MONTH(B50),1) -> 45931 | N50: =IF(G50="","Unknown",G50) -> Pune | O50: =IF(E50="","Unknown",IF(E50<=25,"18-25",IF(E50<=35,"26-35",IF(E50<=45,"36-45",IF(E50<=55,"46-55","56-65"))))) -> Unknown | P50: =COUNTIF($C$2:$C$1001,C50) -> 1 | Q50: =IF(COUNTIF($C$2:C50,C50)=1,1,0) -> 1
A51: ORD100051 | B51: 45715 | C51: CUST1557 | D51: Customer_87 | E51: 39 | F51: Female | G51: Mumbai | H51: Chair | I51: Furniture | J51: 6 | K51: 20561.97 | L51: 123371.82 | M51: =DATE(YEAR(B51),MONTH(B51),1) -> 45689 | N51: =IF(G51="","Unknown",G51) -> Mumbai | O51: =IF(E51="","Unknown",IF(E51<=25,"18-25",IF(E51<=35,"26-35",IF(E51<=45,"36-45",IF(E51<=55,"46-55","56-65"))))) -> 36-45 | P51: =COUNTIF($C$2:$C$1001,C51) -> 1 | Q51: =IF(COUNTIF($C$2:C51,C51)=1,1,0) -> 1
A52: ORD100052 | B52: 45909 | C52: CUST2062 | D52: Customer_254 | E52: 58 | F52: Male | G52: Patna | H52: Book | I52: Education | J52: 10 | K52: 49367.75 | L52: 493677.5 | M52: =DATE(YEAR(B52),MONTH(B52),1) -> 45901 | N52: =IF(G52="","Unknown",G52) -> Patna | O52: =IF(E52="","Unknown",IF(E52<=25,"18-25",IF(E52<=35,"26-35",IF(E52<=45,"36-45",IF(E52<=55,"46-55","56-65"))))) -> 56-65 | P52: =COUNTIF($C$2:$C$1001,C52) -> 1 | Q52: =IF(COUNTIF($C$2:C52,C52)=1,1,0) -> 1
A53: ORD100053 | B53: 45816 | C53: CUST9203 | D53: Customer_70 | E53: 33 | F53: Male | G53: Delhi | H53: Laptop | I53: Electronics | J53: 6 | K53: 4656.1 | L53: 27936.6 | M53: =DATE(YEAR(B53),MONTH(B53),1) -> 45809 | N53: =IF(G53="","Unknown",G53) -> Delhi | O53: =IF(E53="","Unknown",IF(E53<=25,"18-25",IF(E53<=35,"26-35",IF(E53<=45,"36-45",IF(E53<=55,"46-55","56-65"))))) -> 26-35 | P53: =COUNTIF($C$2:$C$1001,C53) -> 1 | Q53: =IF(COUNTIF($C$2:C53,C53)=1,1,0) -> 1
A54: ORD100054 | B54: 45845 | C54: CUST8053 | D54: Customer_408 | E54: 58 | F54: Male | G54: Delhi | H54: Rice | I54: Grocery | J54: 7 | K54: 42345.82 | L54: 296420.74 | M54: =DATE(YEAR(B54),MONTH(B54),1) -> 45839 | N54: =IF(G54="","Unknown",G54) -> Delhi | O54: =IF(E54="","Unknown",IF(E54<=25,"18-25",IF(E54<=35,"26-35",IF(E54<=45,"36-45",IF(E54<=55,"46-55","56-65"))))) -> 56-65 | P54: =COUNTIF($C$2:$C$1001,C54) -> 2 | Q54: =IF(COUNTIF($C$2:C54,C54)=1,1,0) -> 1
A55: ORD100055 | B55: 45763 | C55: CUST1017 | D55: Customer_387 | E55: 42 | F55: Female | G55: Pune | H55: Shoes | I55: Fashion | J55: 7 | K55: 37747.24 | L55: 264230.68 | M55: =DATE(YEAR(B55),MONTH(B55),1) -> 45748 | N55: =IF(G55="","Unknown",G55) -> Pune | O55: =IF(E55="","Unknown",IF(E55<=25,"18-25",IF(E55<=35,"26-35",IF(E55<=45,"36-45",IF(E55<=55,"46-55","56-65"))))) -> 36-45 | P55: =COUNTIF($C$2:$C$1001,C55) -> 1 | Q55: =IF(COUNTIF($C$2:C55,C55)=1,1,0) -> 1
A56: ORD100056 | B56: 45977 | C56: CUST2690 | D56: Customer_11 | E56: 26 | F56: Male | G56: Delhi | H56: Book | I56: Education | J56: 2 | K56: 33304.17 | L56: 66608.34 | M56: =DATE(YEAR(B56),MONTH(B56),1) -> 45962 | N56: =IF(G56="","Unknown",G56) -> Delhi | O56: =IF(E56="","Unknown",IF(E56<=25,"18-25",IF(E56<=35,"26-35",IF(E56<=45,"36-45",IF(E56<=55,"46-55","56-65"))))) -> 26-35 | P56: =COUNTIF($C$2:$C$1001,C56) -> 1 | Q56: =IF(COUNTIF($C$2:C56,C56)=1,1,0) -> 1
A57: ORD100057 | B57: 45998 | C57: CUST2791 | D57: Customer_20 | E57: 58 | F57: Female | G57: Bengaluru | H57: Laptop | I57: Electronics | J57: 6 | K57: 41157.44 | L57: 246944.64 | M57: =DATE(YEAR(B57),MONTH(B57),1) -> 45992 | N57: =IF(G57="","Unknown",G57) -> Bengaluru | O57: =IF(E57="","Unknown",IF(E57<=25,"18-25",IF(E57<=35,"26-35",IF(E57<=45,"36-45",IF(E57<=55,"46-55","56-65"))))) -> 56-65 | P57: =COUNTIF($C$2:$C$1001,C57) -> 1 | Q57: =IF(COUNTIF($C$2:C57,C57)=1,1,0) -> 1
A58: ORD100058 | B58: 45728 | C58: CUST4496 | D58: Customer_53 | E58: 18 | F58: Female | G58: Bengaluru | H58: Chair | I58: Furniture | J58: 7 | K58: 47669.63 | L58: 333687.41 | M58: =DATE(YEAR(B58),MONTH(B58),1) -> 45717 | N58: =IF(G58="","Unknown",G58) -> Bengaluru | O58: =IF(E58="","Unknown",IF(E58<=25,"18-25",IF(E58<=35,"26-35",IF(E58<=45,"36-45",IF(E58<=55,"46-55","56-65"))))) -> 18-25 | P58: =COUNTIF($C$2:$C$1001,C58) -> 1 | Q58: =IF(COUNTIF($C$2:C58,C58)=1,1,0) -> 1
A59: ORD100059 | B59: 46003 | C59: CUST8811 | D59: Customer_115 | E59: 50 | F59: Female | G59: Bengaluru | H59: Chair | I59: Furniture | J59: 1 | K59: 44708.5 | L59: 44708.5 | M59: =DATE(YEAR(B59),MONTH(B59),1) -> 45992 | N59: =IF(G59="","Unknown",G59) -> Bengaluru | O59: =IF(E59="","Unknown",IF(E59<=25,"18-25",IF(E59<=35,"26-35",IF(E59<=45,"36-45",IF(E59<=55,"46-55","56-65"))))) -> 46-55 | P59: =COUNTIF($C$2:$C$1001,C59) -> 1 | Q59: =IF(COUNTIF($C$2:C59,C59)=1,1,0) -> 1
A60: ORD100060 | B60: 45672 | C60: CUST2411 | D60: Customer_292 | E60: 47 | F60: Female | G60: Mumbai | H60: Mobile | I60: Electronics | J60: 5 | K60: 36809.08 | L60: 184045.4 | M60: =DATE(YEAR(B60),MONTH(B60),1) -> 45658 | N60: =IF(G60="","Unknown",G60) -> Mumbai | O60: =IF(E60="","Unknown",IF(E60<=25,"18-25",IF(E60<=35,"26-35",IF(E60<=45,"36-45",IF(E60<=55,"46-55","56-65"))))) -> 46-55 | P60: =COUNTIF($C$2:$C$1001,C60) -> 1 | Q60: =IF(COUNTIF($C$2:C60,C60)=1,1,0) -> 1
A61: ORD100061 | B61: 45969 | C61: CUST2350 | D61: Customer_205 | E61: 46 | F61: Male | G61: Pune | H61: Mobile | I61: Electronics | J61: 4 | K61: 25292.97 | L61: 101171.88 | M61: =DATE(YEAR(B61),MONTH(B61),1) -> 45962 | N61: =IF(G61="","Unknown",G61) -> Pune | O61: =IF(E61="","Unknown",IF(E61<=25,"18-25",IF(E61<=35,"26-35",IF(E61<=45,"36-45",IF(E61<=55,"46-55","56-65"))))) -> 46-55 | P61: =COUNTIF($C$2:$C$1001,C61) -> 1 | Q61: =IF(COUNTIF($C$2:C61,C61)=1,1,0) -> 1
A62: ORD100062 | B62: 45844 | C62: CUST9745 | D62: Customer_48 | E62: 27 | F62: Male | G62: Mumbai | H62: Shoes | I62: Fashion | J62: 1 | K62: 29263.26 | L62: 29263.26 | M62: =DATE(YEAR(B62),MONTH(B62),1) -> 45839 | N62: =IF(G62="","Unknown",G62) -> Mumbai | O62: =IF(E62="","Unknown",IF(E62<=25,"18-25",IF(E62<=35,"26-35",IF(E62<=45,"36-45",IF(E62<=55,"46-55","56-65"))))) -> 26-35 | P62: =COUNTIF($C$2:$C$1001,C62) -> 1 | Q62: =IF(COUNTIF($C$2:C62,C62)=1,1,0) -> 1
... A74: ORD100074 | B74: 45995 | C74: CUST7587 | D74: Customer_223 | E74: 27 | F74: Male | G74: Pune | H74: Laptop | I74: Electronics | J74: 9 | K74: 45419.62 | L74: 408776.58 | M74: =DATE(YEAR(B74),MONTH(B74),1) -> 45992 | N74: =IF(G74="","Unknown",G74) -> Pune | O74: =IF(E74="","Unknown",IF(E74<=25,"18-25",IF(E74<=35,"26-35",IF(E74<=45,"36-45",IF(E74<=55,"46-55","56-65"))))) -> 26-35 | P74: =COUNTIF($C$2:$C$1001,C74) -> 1 | Q74: =IF(COUNTIF($C$2:C74,C74)=1,1,0) -> 1
A75: ORD100075 | B75: 45746 | C75: CUST2157 | D75: Customer_31 | E75: 58 | F75: Male | H75: Mobile | I75: Electronics | J75: 4 | K75: 21599.26 | L75: 86397.04 | M75: =DATE(YEAR(B75),MONTH(B75),1) -> 45717 | N75: =IF(G75="","Unknown",G75) -> Unknown | O75: =IF(E75="","Unknown",IF(E75<=25,"18-25",IF(E75<=35,"26-35",IF(E75<=45,"36-45",IF(E75<=55,"46-55","56-65"))))) -> 56-65 | P75: =COUNTIF($C$2:$C$1001,C75) -> 1 | Q75: =IF(COUNTIF($C$2:C75,C75)=1,1,0) -> 1
A76: ORD100076 | B76: 46021 | C76: CUST8430 | D76: Customer_277 | E76: 45 | F76: Male | G76: Gaya | H76: Laptop | I76: Electronics | J76: 2 | K76: 8883.45 | L76: 17766.9 | M76: =DATE(YEAR(B76),MONTH(B76),1) -> 45992 | N76: =IF(G76="","Unknown",G76) -> Gaya | O76: =IF(E76="","Unknown",IF(E76<=25,"18-25",IF(E76<=35,"26-35",IF(E76<=45,"36-45",IF(E76<=55,"46-55","56-65"))))) -> 36-45 | P76: =COUNTIF($C$2:$C$1001,C76) -> 1 | Q76: =IF(COUNTIF($C$2:C76,C76)=1,1,0) -> 1
A77: ORD100077 | B77: 46018 | C77: CUST1956 | D77: Customer_317 | E77: 22 | F77: Female | G77: Bengaluru | H77: Shoes | I77: Fashion | J77: 9 | K77: 12290.45 | L77: 110614.05 | M77: =DATE(YEAR(B77),MONTH(B77),1) -> 45992 | N77: =IF(G77="","Unknown",G77) -> Bengaluru | O77: =IF(E77="","Unknown",IF(E77<=25,"18-25",IF(E77<=35,"26-35",IF(E77<=45,"36-45",IF(E77<=55,"46-55","56-65"))))) -> 18-25 | P77: =COUNTIF($C$2:$C$1001,C77) -> 1 | Q77: =IF(COUNTIF($C$2:C77,C77)=1,1,0) -> 1
A78: ORD100078 | B78: 45761 | C78: CUST9846 | D78: Customer_298 | E78: 58 | F78: Female | G78: Patna | H78: Book | I78: Education | J78: 6 | K78: 10784.64 | L78: 64707.84 | M78: =DATE(YEAR(B78),MONTH(B78),1) -> 45748 | N78: =IF(G78="","Unknown",G78) -> Patna | O78: =IF(E78="","Unknown",IF(E78<=25,"18-25",IF(E78<=35,"26-35",IF(E78<=45,"36-45",IF(E78<=55,"46-55","56-65"))))) -> 56-65 | P78: =COUNTIF($C$2:$C$1001,C78) -> 1 | Q78: =IF(COUNTIF($C$2:C78,C78)=1,1,0) -> 1
A79: ORD100079 | B79: 46023 | C79: CUST4706 | D79: Customer_34 | E79: 62 | F79: Female | G79: Delhi | H79: Rice | I79: Grocery | J79: 1 | K79: 35862.34 | L79: 35862.34 | M79: =DATE(YEAR(B79),MONTH(B79),1) -> 46023 | N79: =IF(G79="","Unknown",G79) -> Delhi | O79: =IF(E79="","Unknown",IF(E79<=25,"18-25",IF(E79<=35,"26-35",IF(E79<=45,"36-45",IF(E79<=55,"46-55","56-65"))))) -> 56-65 | P79: =COUNTIF($C$2:$C$1001,C79) -> 2 | Q79: =IF(COUNTIF($C$2:C79,C79)=1,1,0) -> 1
A80: ORD100080 | B80: 45890 | C80: CUST5607 | D80: Customer_265 | E80: 61 | F80: Female | G80: Gaya | H80: Rice | I80: Grocery | J80: 1 | K80: 13129.64 | L80: 13129.64 | M80: =DATE(YEAR(B80),MONTH(B80),1) -> 45870 | N80: =IF(G80="","Unknown",G80) -> Gaya | O80: =IF(E80="","Unknown",IF(E80<=25,"18-25",IF(E80<=35,"26-35",IF(E80<=45,"36-45",IF(E80<=55,"46-55","56-65"))))) -> 56-65 | P80: =COUNTIF($C$2:$C$1001,C80) -> 1 | Q80: =IF(COUNTIF($C$2:C80,C80)=1,1,0) -> 1
A81: ORD100081 | B81: 45721 | C81: CUST8211 | D81: Customer_62 | E81: 19 | F81: Female | G81: Gaya | H81: Chair | I81: Furniture | J81: 9 | K81: 45747.37 | L81: 411726.33 | M81: =DATE(YEAR(B81),MONTH(B81),1) -> 45717 | N81: =IF(G81="","Unknown",G81) -> Gaya | O81: =IF(E81="","Unknown",IF(E81<=25,"18-25",IF(E81<=35,"26-35",IF(E81<=45,"36-45",IF(E81<=55,"46-55","56-65"))))) -> 18-25 | P81: =COUNTIF($C$2:$C$1001,C81) -> 1 | Q81: =IF(COUNTIF($C$2:C81,C81)=1,1,0) -> 1
A82: ORD100082 | B82: 45901 | C82: CUST5367 | D82: Customer_499 | E82: 25 | F82: Female | G82: Hyderabad | H82: Book | I82: Education | J82: 6 | K82: 5849.89 | L82: 35099.34 | M82: =DATE(YEAR(B82),MONTH(B82),1) -> 45901 | N82: =IF(G82="","Unknown",G82) -> Hyderabad | O82: =IF(E82="","Unknown",IF(E82<=25,"18-25",IF(E82<=35,"26-35",IF(E82<=45,"36-45",IF(E82<=55,"46-55","56-65"))))) -> 18-25 | P82: =COUNTIF($C$2:$C$1001,C82) -> 1 | Q82: =IF(COUNTIF($C$2:C82,C82)=1,1,0) -> 1
A83: ORD100083 | B83: 45663 | C83: CUST8346 | D83: Customer_384 | E83: 30 | F83: Male | G83: Hyderabad | H83: Laptop | I83: Electronics | J83: 9 | K83: 48845.5 | L83: 439609.5 | M83: =DATE(YEAR(B83),MONTH(B83),1) -> 45658 | N83: =IF(G83="","Unknown",G83) -> Hyderabad | O83: =IF(E83="","Unknown",IF(E83<=25,"18-25",IF(E83<=35,"26-35",IF(E83<=45,"36-45",IF(E83<=55,"46-55","56-65"))))) -> 26-35 | P83: =COUNTIF($C$2:$C$1001,C83) -> 1 | Q83: =IF(COUNTIF($C$2:C83,C83)=1,1,0) -> 1
A84: ORD100084 | B84: 45954 | C84: CUST7484 | D84: Customer_478 | E84: 36 | F84: Male | G84: Gaya | H84: Book | I84: Education | J84: 9 | K84: 24828.05 | L84: 223452.45 | M84: =DATE(YEAR(B84),MONTH(B84),1) -> 45931 | N84: =IF(G84="","Unknown",G84) -> Gaya | O84: =IF(E84="","Unknown",IF(E84<=25,"18-25",IF(E84<=35,"26-35",IF(E84<=45,"36-45",IF(E84<=55,"46-55","56-65"))))) -> 36-45 | P84: =COUNTIF($C$2:$C$1001,C84) -> 1 | Q84: =IF(COUNTIF($C$2:C84,C84)=1,1,0) -> 1
A85: ORD100085 | B85: 45723 | C85: CUST7911 | D85: Customer_7 | E85: 59 | F85: Male | G85: Delhi | H85: Mobile | I85: Electronics | J85: 8 | K85: 17841.4 | L85: 142731.2 | M85: =DATE(YEAR(B85),MONTH(B85),1) -> 45717 | N85: =IF(G85="","Unknown",G85) -> Delhi | O85: =IF(E85="","Unknown",IF(E85<=25,"18-25",IF(E85<=35,"26-35",IF(E85<=45,"36-45",IF(E85<=55,"46-55","56-65"))))) -> 56-65 | P85: =COUNTIF($C$2:$C$1001,C85) -> 1 | Q85: =IF(COUNTIF($C$2:C85,C85)=1,1,0) -> 1
A86: ORD100086 | B86: 45893 | C86: CUST4229 | D86: Customer_234 | E86: 51 | F86: Male | G86: Hyderabad | H86: Book | I86: Education | J86: 10 | K86: 13662.66 | L86: 136626.6 | M86: =DATE(YEAR(B86),MONTH(B86),1) -> 45870 | N86: =IF(G86="","Unknown",G86) -> Hyderabad | O86: =IF(E86="","Unknown",IF(E86<=25,"18-25",IF(E86<=35,"26-35",IF(E86<=45,"36-45",IF(E86<=55,"46-55","56-65"))))) -> 46-55 | P86: =COUNTIF($C$2:$C$1001,C86) -> 1 | Q86: =IF(COUNTIF($C$2:C86,C86)=1,1,0) -> 1
...
